Workbook

Sheet 模板
C1: 销售订单
C2: 需求方（甲方）： | E2: 小象团（专票）
C3: 供货方（乙方）： | E3: 广州启航化妆品科技有限公司 | H3: 订单日期： | I3: 2026/5/1-2026/5/31
H4: 运费承担方式： | I4: 需方承担
C5: 1、产品名称、规格及型号、数量、单价、数量：
C6: 序号 | D6: 产品名称 | F6: 单位 | G6: 数量 | H6: 单价（人民币） | I6: 金额（元） | J6: 备注
B7: =IF(ROW(A1)>MAX(订单!$B:$B),"",ROW(A1)) | C7: 1 | D7: =IFERROR(IF($B7="","",VLOOKUP($B7,订单!$B$2:$J$29583,3,FALSE)),"") | F7: =IFERROR(IF($B7="","",VLOOKUP($B7,订单!$B$2:$J$29589,MATCH(F$6,订单!$B$1:$I$1,0),FALSE)),"") | G7: =IFERROR(IF($B7="","",VLOOKUP($B7,订单!$B$2:$J$29589,MATCH(G$6,订单!$B$1:$I$1,0),FALSE)),"") | H7: =IFERROR(IF($B7="","",VLOOKUP($B7,订单!$B$2:$J$29589,MATCH(H$6,订单!$B$1:$I$1,0),FALSE)),"") | I7: =IFERROR(IF($B7="","",VLOOKUP($B7,订单!$B$2:$J$29589,MATCH(I$6,订单!$B$1:$I$1,0),FALSE)),"") | J7: =IFERROR(IF($B7="","",VLOOKUP($B7,订单!$B$2:$J$29589,MATCH(J$6,订单!$B$1:$I$1,0),FALSE)),"")
B8: =IF(ROW(A2)>MAX(订单!$B:$B),"",ROW(A2)) | C8: =ROW()-6 | D8: =IFERROR(IF($B8="","",VLOOKUP($B8,订单!$B$2:$J$29583,3,FALSE)),"") | F8: =IFERROR(IF($B8="","",VLOOKUP($B8,订单!$B$2:$J$29589,MATCH(F$6,订单!$B$1:$I$1,0),FALSE)),"") | G8: =IFERROR(IF($B8="","",VLOOKUP($B8,订单!$B$2:$J$29589,MATCH(G$6,订单!$B$1:$I$1,0),FALSE)),"") | H8: =IFERROR(IF($B8="","",VLOOKUP($B8,订单!$B$2:$J$29589,MATCH(H$6,订单!$B$1:$I$1,0),FALSE)),"") | I8: =IFERROR(IF($B8="","",VLOOKUP($B8,订单!$B$2:$J$29589,MATCH(I$6,订单!$B$1:$I$1,0),FALSE)),"") | J8: =IFERROR(IF($B8="","",VLOOKUP($B8,订单!$B$2:$J$29589,MATCH(J$6,订单!$B$1:$I$1,0),FALSE)),"")
B9: =IF(ROW(A3)>MAX(订单!$B:$B),"",ROW(A3)) | C9: =ROW()-6 | D9: =IFERROR(IF($B9="","",VLOOKUP($B9,订单!$B$2:$J$29583,3,FALSE)),"") | F9: =IFERROR(IF($B9="","",VLOOKUP($B9,订单!$B$2:$J$29589,MATCH(F$6,订单!$B$1:$I$1,0),FALSE)),"") | G9: =IFERROR(IF($B9="","",VLOOKUP($B9,订单!$B$2:$J$29589,MATCH(G$6,订单!$B$1:$I$1,0),FALSE)),"") | H9: =IFERROR(IF($B9="","",VLOOKUP($B9,订单!$B$2:$J$29589,MATCH(H$6,订单!$B$1:$I$1,0),FALSE)),"") | I9: =IFERROR(IF($B9="","",VLOOKUP($B9,订单!$B$2:$J$29589,MATCH(I$6,订单!$B$1:$I$1,0),FALSE)),"") | J9: =IFERROR(IF($B9="","",VLOOKUP($B9,订单!$B$2:$J$29589,MATCH(J$6,订单!$B$1:$I$1,0),FALSE)),"")
B10: =IF(ROW(A4)>MAX(订单!$B:$B),"",ROW(A4)) | C10: =ROW()-6 | D10: =IFERROR(IF($B10="","",VLOOKUP($B10,订单!$B$2:$J$29583,3,FALSE)),"") | F10: =IFERROR(IF($B10="","",VLOOKUP($B10,订单!$B$2:$J$29589,MATCH(F$6,订单!$B$1:$I$1,0),FALSE)),"") | G10: =IFERROR(IF($B10="","",VLOOKUP($B10,订单!$B$2:$J$29589,MATCH(G$6,订单!$B$1:$I$1,0),FALSE)),"") | H10: =IFERROR(IF($B10="","",VLOOKUP($B10,订单!$B$2:$J$29589,MATCH(H$6,订单!$B$1:$I$1,0),FALSE)),"") | I10: =IFERROR(IF($B10="","",VLOOKUP($B10,订单!$B$2:$J$29589,MATCH(I$6,订单!$B$1:$I$1,0),FALSE)),"") | J10: =IFERROR(IF($B10="","",VLOOKUP($B10,订单!$B$2:$J$29589,MATCH(J$6,订单!$B$1:$I$1,0),FALSE)),"")
B11: =IF(ROW(A5)>MAX(订单!$B:$B),"",ROW(A5)) | C11: =ROW()-6 | D11: =IFERROR(IF($B11="","",VLOOKUP($B11,订单!$B$2:$J$29583,3,FALSE)),"") | F11: =IFERROR(IF($B11="","",VLOOKUP($B11,订单!$B$2:$J$29589,MATCH(F$6,订单!$B$1:$I$1,0),FALSE)),"") | G11: =IFERROR(IF($B11="","",VLOOKUP($B11,订单!$B$2:$J$29589,MATCH(G$6,订单!$B$1:$I$1,0),FALSE)),"") | H11: =IFERROR(IF($B11="","",VLOOKUP($B11,订单!$B$2:$J$29589,MATCH(H$6,订单!$B$1:$I$1,0),FALSE)),"") | I11: =IFERROR(IF($B11="","",VLOOKUP($B11,订单!$B$2:$J$29589,MATCH(I$6,订单!$B$1:$I$1,0),FALSE)),"") | J11: =IFERROR(IF($B11="","",VLOOKUP($B11,订单!$B$2:$J$29589,MATCH(J$6,订单!$B$1:$I$1,0),FALSE)),"")
B12: =IF(ROW(A6)>MAX(订单!$B:$B),"",ROW(A6)) | C12: =ROW()-6 | D12: =IFERROR(IF($B12="","",VLOOKUP($B12,订单!$B$2:$J$29583,3,FALSE)),"") | F12: =IFERROR(IF($B12="","",VLOOKUP($B12,订单!$B$2:$J$29589,MATCH(F$6,订单!$B$1:$I$1,0),FALSE)),"") | G12: =IFERROR(IF($B12="","",VLOOKUP($B12,订单!$B$2:$J$29589,MATCH(G$6,订单!$B$1:$I$1,0),FALSE)),"") | H12: =IFERROR(IF($B12="","",VLOOKUP($B12,订单!$B$2:$J$29589,MATCH(H$6,订单!$B$1:$I$1,0),FALSE)),"") | I12: =IFERROR(IF($B12="","",VLOOKUP($B12,订单!$B$2:$J$29589,MATCH(I$6,订单!$B$1:$I$1,0),FALSE)),"") | J12: =IFERROR(IF($B12="","",VLOOKUP($B12,订单!$B$2:$J$29589,MATCH(J$6,订单!$B$1:$I$1,0),FALSE)),"")
B13: =IF(ROW(A7)>MAX(订单!$B:$B),"",ROW(A7)) | C13: =ROW()-6 | D13: =IFERROR(IF($B13="","",VLOOKUP($B13,订单!$B$2:$J$29583,3,FALSE)),"") | F13: =IFERROR(IF($B13="","",VLOOKUP($B13,订单!$B$2:$J$29589,MATCH(F$6,订单!$B$1:$I$1,0),FALSE)),"") | G13: =IFERROR(IF($B13="","",VLOOKUP($B13,订单!$B$2:$J$29589,MATCH(G$6,订单!$B$1:$I$1,0),FALSE)),"") | H13: =IFERROR(IF($B13="","",VLOOKUP($B13,订单!$B$2:$J$29589,MATCH(H$6,订单!$B$1:$I$1,0),FALSE)),"") | I13: =IFERROR(IF($B13="","",VLOOKUP($B13,订单!$B$2:$J$29589,MATCH(I$6,订单!$B$1:$I$1,0),FALSE)),"") | J13: =IFERROR(IF($B13="","",VLOOKUP($B13,订单!$B$2:$J$29589,MATCH(J$6,订单!$B$1:$I$1,0),FALSE)),"")
B14: =IF(ROW(A8)>MAX(订单!$B:$B),"",ROW(A8)) | C14: =ROW()-6 | D14: =IFERROR(IF($B14="","",VLOOKUP($B14,订单!$B$2:$J$29583,3,FALSE)),"") | F14: =IFERROR(IF($B14="","",VLOOKUP($B14,订单!$B$2:$J$29589,MATCH(F$6,订单!$B$1:$I$1,0),FALSE)),"") | G14: =IFERROR(IF($B14="","",VLOOKUP($B14,订单!$B$2:$J$29589,MATCH(G$6,订单!$B$1:$I$1,0),FALSE)),"") | H14: =IFERROR(IF($B14="","",VLOOKUP($B14,订单!$B$2:$J$29589,MATCH(H$6,订单!$B$1:$I$1,0),FALSE)),"") | I14: =IFERROR(IF($B14="","",VLOOKUP($B14,订单!$B$2:$J$29589,MATCH(I$6,订单!$B$1:$I$1,0),FALSE)),"") | J14: =IFERROR(IF($B14="","",VLOOKUP($B14,订单!$B$2:$J$29589,MATCH(J$6,订单!$B$1:$I$1,0),FALSE)),"")
B15: =IF(ROW(A9)>MAX(订单!$B:$B),"",ROW(A9)) | C15: =ROW()-6 | D15: =IFERROR(IF($B15="","",VLOOKUP($B15,订单!$B$2:$J$29583,3,FALSE)),"") | F15: =IFERROR(IF($B15="","",VLOOKUP($B15,订单!$B$2:$J$29589,MATCH(F$6,订单!$B$1:$I$1,0),FALSE)),"") | G15: =IFERROR(IF($B15="","",VLOOKUP($B15,订单!$B$2:$J$29589,MATCH(G$6,订单!$B$1:$I$1,0),FALSE)),"") | H15: =IFERROR(IF($B15="","",VLOOKUP($B15,订单!$B$2:$J$29589,MATCH(H$6,订单!$B$1:$I$1,0),FALSE)),"") | I15: =IFERROR(IF($B15="","",VLOOKUP($B15,订单!$B$2:$J$29589,MATCH(I$6,订单!$B$1:$I$1,0),FALSE)),"") | J15: =IFERROR(IF($B15="","",VLOOKUP($B15,订单!$B$2:$J$29589,MATCH(J$6,订单!$B$1:$I$1,0),FALSE)),"")
B16: =IF(ROW(A10)>MAX(订单!$B:$B),"",ROW(A10)) | C16: =ROW()-6 | D16: =IFERROR(IF($B16="","",VLOOKUP($B16,订单!$B$2:$J$29583,3,FALSE)),"") | F16: =IFERROR(IF($B16="","",VLOOKUP($B16,订单!$B$2:$J$29589,MATCH(F$6,订单!$B$1:$I$1,0),FALSE)),"") | G16: =IFERROR(IF($B16="","",VLOOKUP($B16,订单!$B$2:$J$29589,MATCH(G$6,订单!$B$1:$I$1,0),FALSE)),"") | H16: =IFERROR(IF($B16="","",VLOOKUP($B16,订单!$B$2:$J$29589,MATCH(H$6,订单!$B$1:$I$1,0),FALSE)),"") | I16: =IFERROR(IF($B16="","",VLOOKUP($B16,订单!$B$2:$J$29589,MATCH(I$6,订单!$B$1:$I$1,0),FALSE)),"") | J16: =IFERROR(IF($B16="","",VLOOKUP($B16,订单!$B$2:$J$29589,MATCH(J$6,订单!$B$1:$I$1,0),FALSE)),"")
B17: =IF(ROW(A11)>MAX(订单!$B:$B),"",ROW(A11)) | C17: =ROW()-6 | D17: =IFERROR(IF($B17="","",VLOOKUP($B17,订单!$B$2:$J$29583,3,FALSE)),"") | F17: =IFERROR(IF($B17="","",VLOOKUP($B17,订单!$B$2:$J$29589,MATCH(F$6,订单!$B$1:$I$1,0),FALSE)),"") | G17: =IFERROR(IF($B17="","",VLOOKUP($B17,订单!$B$2:$J$29589,MATCH(G$6,订单!$B$1:$I$1,0),FALSE)),"") | H17: =IFERROR(IF($B17="","",VLOOKUP($B17,订单!$B$2:$J$29589,MATCH(H$6,订单!$B$1:$I$1,0),FALSE)),"") | I17: =IFERROR(IF($B17="","",VLOOKUP($B17,订单!$B$2:$J$29589,MATCH(I$6,订单!$B$1:$I$1,0),FALSE)),"") | J17: =IFERROR(IF($B17="","",VLOOKUP($B17,订单!$B$2:$J$29589,MATCH(J$6,订单!$B$1:$I$1,0),FALSE)),"")
B18: =IF(ROW(A12)>MAX(订单!$B:$B),"",ROW(A12)) | C18: =ROW()-6 | D18: =IFERROR(IF($B18="","",VLOOKUP($B18,订单!$B$2:$J$29583,3,FALSE)),"") | F18: =IFERROR(IF($B18="","",VLOOKUP($B18,订单!$B$2:$J$29589,MATCH(F$6,订单!$B$1:$I$1,0),FALSE)),"") | G18: =IFERROR(IF($B18="","",VLOOKUP($B18,订单!$B$2:$J$29589,MATCH(G$6,订单!$B$1:$I$1,0),FALSE)),"") | H18: =IFERROR(IF($B18="","",VLOOKUP($B18,订单!$B$2:$J$29589,MATCH(H$6,订单!$B$1:$I$1,0),FALSE)),"") | I18: =IFERROR(IF($B18="","",VLOOKUP($B18,订单!$B$2:$J$29589,MATCH(I$6,订单!$B$1:$I$1,0),FALSE)),"") | J18: =IFERROR(IF($B18="","",VLOOKUP($B18,订单!$B$2:$J$29589,MATCH(J$6,订单!$B$1:$I$1,0),FALSE)),"")
B19: =IF(ROW(A13)>MAX(订单!$B:$B),"",ROW(A13)) | C19: =ROW()-6 | D19: =IFERROR(IF($B19="","",VLOOKUP($B19,订单!$B$2:$J$29583,3,FALSE)),"") | F19: =IFERROR(IF($B19="","",VLOOKUP($B19,订单!$B$2:$J$29589,MATCH(F$6,订单!$B$1:$I$1,0),FALSE)),"") | G19: =IFERROR(IF($B19="","",VLOOKUP($B19,订单!$B$2:$J$29589,MATCH(G$6,订单!$B$1:$I$1,0),FALSE)),"") | H19: =IFERROR(IF($B19="","",VLOOKUP($B19,订单!$B$2:$J$29589,MATCH(H$6,订单!$B$1:$I$1,0),FALSE)),"") | I19: =IFERROR(IF($B19="","",VLOOKUP($B19,订单!$B$2:$J$29589,MATCH(I$6,订单!$B$1:$I$1,0),FALSE)),"") | J19: =IFERROR(IF($B19="","",VLOOKUP($B19,订单!$B$2:$J$29589,MATCH(J$6,订单!$B$1:$I$1,0),FALSE)),"")
... B156: =IF(ROW(A150)>MAX(订单!$B:$B),"",ROW(A150)) | C156: =ROW()-6 | D156: =IFERROR(IF($B156="","",VLOOKUP($B156,订单!$B$2:$J$29583,3,FALSE)),"") | F156: =IFERROR(IF($B156="","",VLOOKUP($B156,订单!$B$2:$J$29589,MATCH(F$6,订单!$B$1:$I$1,0),FALSE)),"") | G156: =IFERROR(IF($B156="","",VLOOKUP($B156,订单!$B$2:$J$29589,MATCH(G$6,订单!$B$1:$I$1,0),FALSE)),"") | H156: =IFERROR(IF($B156="","",VLOOKUP($B156,订单!$B$2:$J$29589,MATCH(H$6,订单!$B$1:$I$1,0),FALSE)),"") | I156: =IFERROR(IF($B156="","",VLOOKUP($B156,订单!$B$2:$J$29589,MATCH(I$6,订单!$B$1:$I$1,0),FALSE)),"") | J156: =IFERROR(IF($B156="","",VLOOKUP($B156,订单!$B$2:$J$29589,MATCH(J$6,订单!$B$1:$I$1,0),FALSE)),"")
C157: 合计 | G157: =SUM(G7:G156) | I157: =SUM(I7:I156)
C158: 总合计（大写） | E158: =IF(I157="","",(IF(I157=0,"零元",TEXT(LEFT(DOLLAR(I157),LEN(DOLLAR(I157))-3),"[>0][dbnum2]G/通用格式元;;;")&TEXT(RIGHT(DOLLAR(I157),2),"[dbnum2]0角0分;;整")))) | H158: （小写）： | I158: =I157
C159: 2、交货期：合同生效后且收到订单全额货款后2-7日内发货（特殊情况协商解决）。
C160: 3、运输方式及地点：物流运输或其他运输方式，地点：需方在本订单中指定的收货地点。
C161: 收货地址：/
C162: 4、运输方式及费用负担：物流或其他货运方式。运费由需方承担。在需方收货并理货后，若因运输导致产品损毁发生纠纷的，由承运方解决，供方协助解决。
C163: 5、发票：商品完成退货周期后的10个工作日，双方确认订单货款已经结清的情况下，供方需将对应的增值税专用发票或者增值税普通发票开具给需求方。
C164: 6、包装标准：按符合产品特性或要求的标准执行
C165: 7、验收标准：按照商品质量管理条例验收，需方应在收货验货后申请退货/换货，需方收货验货无异议视为全部验收合格。若由于产品质量或物流问题导致需方平台无法按时发货，需协商解决。
C166: 8、违约责任：按《中华人民共和国民法典》处理，有关诉讼问题，向供方注册所在地人民法院提起诉讼。
C167: 9、关于售后，属于产品质量问题由供方处理。
C168: 10、本订单一式贰份，供方、需方各执壹份，双方签字（盖章）后生效。
C169: 需方： | F169: 供方：
C170: 单位名称： | E170: 小象团（专票） | F170: 单位名称： | G170: 广州启航化妆品科技有限公司
C171: 单位地址： | E171: 厦门市海沧区海沧大道891号705单元之一 | F171: 单位地址： | G171: 广州市天河区花城大道20号1301房之五
C172: 代表签字： | F172: 代表签字：
C173: 电 话： | E173: 15659810753 | F173: 电 话： | G173: 020-85676088
C174: 开户银行： | E174: 中国农业银行股份有限公司厦门保税港支行 | F174: 开户银行： | G174: 广州农业银行五羊新城支行
C175: 账 号： | F175: 账 号： | G175: 44031701040024156
C176: 统一社会信用代码： | E176: 91350200MA2YRC1D4B | F176: 统一社会信用代码： | G176: 91440101MA5CLE6G92

Sheet 开票信息
A1: ﻿合同名称 | B1: 票据类型 | C1: 单位名称 | D1: 单位地址 | E1: 代表签字 | F1: 电 话 | G1: 开户银行 | H1: 账 号 | I1: 统一社会信用代码
A2: 豆妈国际 | B2: 专票 | C2: 上海麟璇国际贸易有限公司 | F2: 17521734768 | G2: 建行上海春申支行 | H2: 31050169550000000262 | I2: 91310112MA1GC99J66
A3: 百合(澜清) | B3: 专票 | C3: 石家庄澜清信息技术有限公司 | D3: 石家庄市长安区平安北大街18号乐模商城南座1416室 | F3: 15227886686 | G3: 中国民生银行股份有限公司石家庄翟营南大街支行 | H3: 602678666 | I3: 91130102094838639T
A4: 甘肃亿呈商贸 | B4: 专票 | C4: 甘肃亿呈商贸有限公司 | D4: 甘肃省兰州市城关区南滨河东路5222号名城广场3号写字楼10楼1011室 | F4: 0931-8431214 | G4: 中国建设银行股份有限公司兰州南昌路支行 | H4: 62050136002600000097 | I4: 91620102 MA73 264B 5Q
A5: 广州珀瑞丝 | B5: 专票 | C5: 广州珀瑞丝化妆品有限公司 | D5: 广州市白云区鹤龙街细彭岭路10号汇龙国际电商产业园C栋607室 | F5: 020-29031126 | G5: 平安银行广州万达广场支行 | H5: 15079171820014 | I5: 91440106MACB55421B
A6: 富德隆 | B6: 专票 | C6: 深圳市富德隆科技有限公司 | D6: 深圳市龙岗区平湖街道平湖社区平湖大道满庭芳花园5栋2单元504 | F6: 13714636790 | G6: 中国建设银行股份有限公司深圳市分行 | H6: 44201501100052545830 | I6: 914403000539900951
A7: 喜辉以禾 | B7: 专票 | C7: 喜辉以禾实业(上海)有限公司 | D7: 上海市嘉定区众仁路399号1幢12层B区JT13943室 | F7: 13622336490 | G7: 中国银行上海市博乐路支行 | H7: 437788596776 | I7: 91310114MAE6627T8U
A8: 上海蕤翔实业有限公司 | B8: 专票 | C8: 上海蕤翔实业有限公司 | D8: 上海市普陀区绥德路555号D栋508 | F8: 17602100116 | G8: 中国银行上海市桃浦支行 | H8: 453385607416 | I8: 91310107MACXJ1KC09
A9: 上海心满 | C9: 上海心满商贸有限公司 | D9: 上海市嘉定区嘉罗公路1661弄12号101室J557 | F9: 021-59558669 | G9: 中国农业银行股份有限公司上海闵行虹桥支行 | H9: 03407500040030659 | I9: 91310114MA1GTURW7R
A10: 宁波晟淘 | B10: 专票
A11: 中盛瑞尔 | B11: 专票
A12: 荃心商贸 | B12: 专票 | C12: 杭州荃心商贸有限公司 | D12: 浙江省杭州市余杭区五常街道邦帮金座2幢 | F12: 57185063196 | G12: 中国农业银行杭州古荡支行 | H12: 19000801040017866 | I12: 91330110MA2B00641X
A13: 清滋 | B13: 专票 | C13: 上海清滋商贸有限公司 | D13: 浦东新区万祥镇宏祥北路83弄1-42号20幢118室 31391827 | F13: 18916357868 | G13: 中国工商银行上海市甘泉新村支行 | H13: 1001042209000004540 | I13: 91310115MA1H8F0W05
A14: 才赋 | B14: 专票 | C14: 上海才赋人力资源科技有限公司 | D14: 上海市普陀区大渡河路556弄1号国浩长风城南座1101室 | F14: 8621-32581281 | G14: 招商银行上海分行虹桥支行 | H14: 1219 2401 8610 702 | I14: 91310107MA1G0DTX3H
A15: 快愉 | B15: 嘉博专票 | C15: 嘉博伟创（江苏）贸易有限公司 | D15: 镇江市京口区中山东路301号苏宁广场塔楼A 单元1305室 | F15: 15651287585 | G15: 农行镇江京口支行 | H15: 10311101040241705 | I15: 91321102MA27M93K4L
A16: 快愉 | B16: 快愉专票 | C16: 快愉（上海）电子商务有限公司 | D16: 上海市宝山区潘泾路5777弄188号3层3274室 | F16: 15651287585 | G16: 中国农业银行股份有限公司上海真北路支行 | H16: 03477400040014738 | I16: 91310120067750631Q
A17: 和润晟(专票) | C17: 山西和润晟贸易有限公司 | D17: 山西省太原市万柏林区迎泽西大街100号国际能源中心26层2605-1室 | F17: 18334789091 | G17: 中国工商银行股份有限公司太原迎泽支行 | H17: 0502207009200052158 | I17: 91140100MA0M0PGC56
A18: 九美子 | B18: 长沙赛尔专票 | C18: 长沙赛尔贸易有限公司 | D18: 长沙市雨花区南二环一段路55号叠彩峰苑B区2栋1802房 | G18: 中信银行长沙人民路支行 | H18: 8111 6010 11700 581910 | I18: 91430111MA4R7DQ16A
A19: 九美子 | B19: 上海冰雾专票 | C19: 上海冰雾网络科技有限公司 | D19: 上海市闵行区联川路319号3幢205室 | F19: 021-60960807 | G19: 中国民生银行股份有限公司上海南汇支行 | H19: 159660157 | I19: 91310112MA1GCHQX0X
A20: 上海敏君 | B20: 专票 | C20: 上海敏君实业有限公司 | D20: 上海市青浦区徐泾镇双联路388号2号楼7楼 | F20: 021-31781587 | G20: 浙江泰隆银行上海嘉定支行 | H20: 3101050120100015551 | I20: 91310113062571220C
A21: 鑫万齐 | B21: 专票 | C21: 鑫万齐（天津）科技有限公司 | D21: 天津经济技术开发区滨海-中关村科技园融汇商务5区1号楼二层-78号 | F21: 18201140387 | G21: 招商银行股份有限公司天津南京路支行（回款账户首选） | H21: 122917517910001 | I21: 91120116MACPUGA53J
A22: 颐佰(专票)剩下的金金开
A23: 全晟商贸 | B23: 专票 | C23: 山东全晟商贸有限公司 | D23: 山东省日照市经济开发区北京路277号航贸中心A座2101 | G23: 中国农业银行股份有限公司日照市分行 | H23: 15651001040052755 | I23: 91371103MA954NM10F
A24: 先迈网 | B24: 专票 | C24: 大连好麦檬信息科技有限公司 | D24: 辽宁省大连经济技术开发区城润万家78栋-4号 | F24: 18804202893 | G24: 中国民生银行股份有限公司大连金州支行 | H24: 644575079 | I24: 91210213MADA1E5F89
A25: 武汉利尔亿 | B25: 专票 | C25: 武汉利尔亿商贸有限公司 | D25: 武汉市硚口区解放正巷68号 | F25: 027-85676702 | G25: 中国工商银行武汉市汉正街支行 | H25: 3202013509200210117 | I25: 91420104MA4K3EWHX9
A26: bmclub | B26: 专票 | C26: 南京安田羽铭商贸有限公司 | D26: 南京市鼓楼区江东北路88号2412室 | F26: 18651825755 | G26: 中国银行股份有限公司南京云锦路支行 | H26: 546975827242 | I26: 91320106MA256HNQ3G
A27: 柠檬阿姨美妆 | B27: 杭州柠芒椒创普票 | C27: 杭州柠芒椒创电子商务有限公司 | G27: 杭州银行 | H27: 3301 0410 6000 7331444 | I27: 91330113MAK5XF084B
A28: 欧妮 | B28: 家亨专票剩下的金子开 | D28: 安徽省合肥市长丰县双墩镇滁河社区规划支路S2栋B85室 | F28: 17857443206 | G28: 中国工商银行股份有限公司长丰双凤支行 | H28: 1302052309100167043 | I28: 91330282MAC7LUQM78
A29: 欧妮 | B29: 亨浩专票剩下的金子开
A30: 达达妈 | B30: 专票 | C30: 合肥磐韦电子商务有限公司 | D30: 安徽省合肥市长丰县双墩镇濛河路1号创孵中心E821 | F30: 15161459392 | G30: 招商银行股份有限公司合肥瑶海支行 | H30: 551907288510902 | I30: 91340121MA8N1J6P22
A31: 柠月美妆 | B31: 普票剩下的金子开 | C31: 义乌市比先化妆品有限公司 | D31: 浙江省金华市义乌市廿三里街道草湖塘小区3栋一单元307室（自主申报） | F31: 15805799494 | G31: 中国工商银行股份有限公司义乌商城支行营业部 | H31: 1208021409100112956 | I31: 91330782MA2K0KP10E
A32: 知品美妆 | B32: 专票 | C32: 深圳市佰祺电子商务有限公司 | D32: 深圳市龙岗区坂田街道马安堂社区环城南路15号恒大都会广场1栋1910-2 | F32: 13005498285 | G32: 广发银行股份有限公司深圳坂田支行 | H32: 9550880231159200141 | I32: 91440300MA5H3KQY6N
A33: 上海宇致 | B33: 专票 | C33: 上海宇致实业有限公司 | D33: 上海市闵行区联川路319号2幢403室 | F33: 021-60960807 | G33: 浙江泰隆商业银行上海周浦支行 | H33: 31010220201000044560 | I33: 91310113312209903Y
A34: 中节能 | B34: 专票 | C34: 中节能环保投资发展（江西）有限公司工会委员会 | D34: 江西省南昌市高新区中节能国际中心1号楼 | I34: 81360000MCA133032F
A35: 雪玲妃专柜正品特价店 | B35: 个人票 | C35: 上海麟璇国际贸易有限公司 | F35: 17521734768 | G35: 建行上海春申支行 | H35: 31050169550000000262 | I35: 91310112MA1GC99J66
A36: zz思密达杂货铺 | B36: 个人票 | C36: 上海麟璇国际贸易有限公司 | F36: 17521734768 | G36: 建行上海春申支行 | H36: 31050169550000000262 | I36: 91310112MA1GC99J66
A37: 大宋宋美妆 | B37: 普票 | C37: 上海黑黛黛品牌管理有限公司 | D37: 上海市金山区亭林镇天工路285弄38号（恒信源经济园区） | F37: 13391126136 | G37: 招商银行股份有限公司上海准中支行 | H37: 121950974010701 | I37: 91310116MACDC1ET54
A38: 一只毛吉吉 | B38: 普票 | C38: 桂林市临桂区有个朋友网络销售经营部 | D38: 临桂区临桂镇桂康鸿湖园D11栋2号 | F38: 18907731385 | G38: 招商银行股份有限公司上海北外滩支行 | H38: 121954641710001 | I38: 92450312MADKKQNM53
A39: 广盈和创 | B39: 专票 | C39: 深圳市广盈和创贸易有限公司 | D39: 深圳市福田区莲花街道福中社区金田路4028号荣超经贸中心A309-AJ84 | F39: 14714932220 | G39: 中国银行深圳北方大厦支行 | H39: 747179152120 | I39: 91440300MAE12U807G
A40: 广盈特联 | B40: 专票 | C40: 广盈特联(深圳)供应链有限公司 | D40: 深圳市福田区华强北街道福强社区振华路中电迪富大厦4层411室 | F40: 13043489506 | G40: 中国农业银行深圳塘朗支行 | H40: 41009800040000873 | I40: 91440300MA5GCXQR2G
...

Sheet 订单
A1: 序号 | B1: 序号 | C1: 需求方（甲方） | D1: 产品名称 | E1: 单位 | F1: 数量 | G1: 单价（人民币） | H1: 金额（元） | I1: 备注 | J1: 销售 | K1: 需求方（甲方）
A2: 1 | B2: =COUNTIF($C$2:$C2,模板!$E$2) | C2: 677design | D2: Lycocelle绽家内衣洗衣液100ml（经典） | F2: 1 | G2: =IFERROR(H2/F2,"") | H2: 0 | J2: 咏琪 | K2: 677design | L2: =COUNTIF($K2:K$2,$K2)
A3: 2 | B3: =COUNTIF($C$2:$C3,模板!$E$2) | C3: 677design | D3: Lycocelle绽家内衣洗衣液330ml（经典） | F3: 1 | G3: =IFERROR(H3/F3,"") | H3: 24 | J3: 咏琪 | K3: 677design | L3: =COUNTIF($K$2:K3,$K3)
A4: 3 | B4: =COUNTIF($C$2:$C4,模板!$E$2) | C4: BBS小鲨鱼 | D4: Lycocelle绽家内衣洗衣液100ml（经典） | F4: 10 | G4: =IFERROR(H4/F4,"") | H4: 0 | J4: 彭珠 | K4: BBS小鲨鱼 | L4: =COUNTIF($K$2:K4,$K4)
A5: 4 | B5: =COUNTIF($C$2:$C5,模板!$E$2) | C5: BBS小鲨鱼 | D5: Lycocelle绽家内衣洗衣液330ml（七月炉火） | F5: 3 | G5: =IFERROR(H5/F5,"") | H5: 73.5 | J5: 彭珠 | K5: BBS小鲨鱼 | L5: =COUNTIF($K$2:K5,$K5)
A6: 5 | B6: =COUNTIF($C$2:$C6,模板!$E$2) | C6: BBS小鲨鱼 | D6: Lycocelle绽家内衣洗衣液330ml（爱丽斯梦境） | F6: 2 | G6: =IFERROR(H6/F6,"") | H6: 49 | J6: 彭珠 | K6: BBS小鲨鱼 | L6: =COUNTIF($K$2:K6,$K6)
A7: 6 | B7: =COUNTIF($C$2:$C7,模板!$E$2) | C7: BBS小鲨鱼 | D7: Lycocelle绽家内衣洗衣液330ml（玫瑰与蔷薇） | F7: 6 | G7: =IFERROR(H7/F7,"") | H7: 147 | J7: 彭珠 | K7: BBS小鲨鱼 | L7: =COUNTIF($K$2:K7,$K7)
A8: 7 | B8: =COUNTIF($C$2:$C8,模板!$E$2) | C8: BBS小鲨鱼 | D8: Lycocelle绽家内衣洗衣液330ml（粉红葡萄柚） | F8: 4 | G8: =IFERROR(H8/F8,"") | H8: 98 | J8: 彭珠 | K8: BBS小鲨鱼 | L8: =COUNTIF($K$2:K8,$K8)
A9: 8 | B9: =COUNTIF($C$2:$C9,模板!$E$2) | C9: BBS小鲨鱼 | D9: Lycocelle绽家内衣洗衣液330ml（经典） | F9: 5 | G9: =IFERROR(H9/F9,"") | H9: 122.5 | J9: 彭珠 | K9: BBS小鲨鱼 | L9: =COUNTIF($K$2:K9,$K9)
A10: 9 | B10: =COUNTIF($C$2:$C10,模板!$E$2) | C10: BBS小鲨鱼 | D10: Lycocelle绽家四季繁花酵素香氛洗衣液480ml（无花果与奶檀）-袋装 | F10: 4 | G10: =IFERROR(H10/F10,"") | H10: 0 | J10: 彭珠 | K10: BBS小鲨鱼 | L10: =COUNTIF($K$2:K10,$K10)
A11: 10 | B11: =COUNTIF($C$2:$C11,模板!$E$2) | C11: BBS小鲨鱼 | D11: Lycocelle绽家四季繁花酵素香氛洗衣液480ml（甜橙与百里香）-袋装 | F11: 2 | G11: =IFERROR(H11/F11,"") | H11: 0 | J11: 彭珠 | K11: BBS小鲨鱼 | L11: =COUNTIF($K$2:K11,$K11)
A12: 11 | B12: =COUNTIF($C$2:$C12,模板!$E$2) | C12: BBS小鲨鱼 | D12: Lycocelle绽家四季繁花酵素香氛洗衣液600ml（无花果与奶檀）-方瓶 | F12: 1 | G12: =IFERROR(H12/F12,"") | H12: 35 | J12: 彭珠 | K12: BBS小鲨鱼 | L12: =COUNTIF($K$2:K12,$K12)
A13: 12 | B13: =COUNTIF($C$2:$C13,模板!$E$2) | C13: BBS小鲨鱼 | D13: Lycocelle绽家四季繁花香氛衣物柔顺剂300ml（桂花与清酒) | F13: 3 | G13: =IFERROR(H13/F13,"") | H13: 0 | J13: 彭珠 | K13: BBS小鲨鱼 | L13: =COUNTIF($K$2:K13,$K13)
A14: 13 | B14: =COUNTIF($C$2:$C14,模板!$E$2) | C14: BBS小鲨鱼 | D14: Lycocelle绽家护衣留香珠（一杯鲜橙）180g | F14: 1 | G14: =IFERROR(H14/F14,"") | H14: 0 | J14: 彭珠 | K14: BBS小鲨鱼 | L14: =COUNTIF($K$2:K14,$K14)
... A79: 78 | B79: =COUNTIF($C$2:$C79,模板!$E$2) | C79: BBS小鲨鱼 | D79: 绽家香水油浓缩洗衣液（雨后檀木鸢尾花）800mL-联名版 | F79: 1 | G79: =IFERROR(H79/F79,"") | H79: 51 | J79: 彭珠 | K79: BBS小鲨鱼 | L79: =COUNTIF($K$2:K79,$K79)
A80: 79 | B80: =COUNTIF($C$2:$C80,模板!$E$2) | C80: =IFERROR(VLOOKUP(K80,开票信息!$A:$C,3,0),"") | D80: Lycocelle绽家内衣洗衣液330ml（爱丽斯梦境） | F80: 6 | G80: =IFERROR(H80/F80,"") | H80: 150 | J80: 秋容 | K80: BMCLUB | L80: =COUNTIF($K$2:K80,$K80)
A81: 80 | B81: =COUNTIF($C$2:$C81,模板!$E$2) | C81: =IFERROR(VLOOKUP(K81,开票信息!$A:$C,3,0),"") | D81: Lycocelle绽家内衣洗衣液330ml（玫瑰与蔷薇） | F81: 5 | G81: =IFERROR(H81/F81,"") | H81: 125 | J81: 秋容 | K81: BMCLUB | L81: =COUNTIF($K$2:K81,$K81)
A82: 81 | B82: =COUNTIF($C$2:$C82,模板!$E$2) | C82: =IFERROR(VLOOKUP(K82,开票信息!$A:$C,3,0),"") | D82: Lycocelle绽家内衣洗衣液330ml（粉红葡萄柚） | F82: 5 | G82: =IFERROR(H82/F82,"") | H82: 125 | J82: 秋容 | K82: BMCLUB | L82: =COUNTIF($K$2:K82,$K82)
A83: 82 | B83: =COUNTIF($C$2:$C83,模板!$E$2) | C83: =IFERROR(VLOOKUP(K83,开票信息!$A:$C,3,0),"") | D83: Lycocelle绽家内衣洗衣液330ml（经典） | F83: 8 | G83: =IFERROR(H83/F83,"") | H83: 200 | J83: 秋容 | K83: BMCLUB | L83: =COUNTIF($K$2:K83,$K83)
A84: 83 | B84: =COUNTIF($C$2:$C84,模板!$E$2) | C84: =IFERROR(VLOOKUP(K84,开票信息!$A:$C,3,0),"") | D84: Lycocelle绽家四季繁花酵素香氛洗衣液480ml（无花果与奶檀）-袋装 | F84: 26 | G84: =IFERROR(H84/F84,"") | H84: 260 | J84: 秋容 | K84: BMCLUB | L84: =COUNTIF($K$2:K84,$K84)
A85: 84 | B85: =COUNTIF($C$2:$C85,模板!$E$2) | C85: =IFERROR(VLOOKUP(K85,开票信息!$A:$C,3,0),"") | D85: Lycocelle绽家四季繁花酵素香氛洗衣液480ml（甜橙与百里香）-袋装 | F85: 13 | G85: =IFERROR(H85/F85,"") | H85: 130 | J85: 秋容 | K85: BMCLUB | L85: =COUNTIF($K$2:K85,$K85)
A86: 85 | B86: =COUNTIF($C$2:$C86,模板!$E$2) | C86: =IFERROR(VLOOKUP(K86,开票信息!$A:$C,3,0),"") | D86: Lycocelle绽家四季繁花酵素香氛洗衣液480ml（迈索尔檀木与小花茉莉）-袋装 | F86: 9 | G86: =IFERROR(H86/F86,"") | H86: 90 | J86: 秋容 | K86: BMCLUB | L86: =COUNTIF($K$2:K86,$K86)
A87: 86 | B87: =COUNTIF($C$2:$C87,模板!$E$2) | C87: =IFERROR(VLOOKUP(K87,开票信息!$A:$C,3,0),"") | D87: Lycocelle绽家四季繁花酵素香氛洗衣液600ml（无花果与奶檀）-方瓶 | F87: 2 | G87: =IFERROR(H87/F87,"") | H87: 36 | J87: 秋容 | K87: BMCLUB | L87: =COUNTIF($K$2:K87,$K87)
A88: 87 | B88: =COUNTIF($C$2:$C88,模板!$E$2) | C88: =IFERROR(VLOOKUP(K88,开票信息!$A:$C,3,0),"") | D88: Lycocelle绽家四季繁花酵素香氛洗衣液600ml（杏仁奶檀）-方瓶 | F88: 1 | G88: =IFERROR(H88/F88,"") | H88: 18 | J88: 秋容 | K88: BMCLUB | L88: =COUNTIF($K$2:K88,$K88)
A89: 88 | B89: =COUNTIF($C$2:$C89,模板!$E$2) | C89: =IFERROR(VLOOKUP(K89,开票信息!$A:$C,3,0),"") | D89: Lycocelle绽家四季繁花酵素香氛洗衣液（迈索尔檀木与小花茉莉）30ml | F89: 7 | G89: =IFERROR(H89/F89,"") | H89: 0 | J89: 秋容 | K89: BMCLUB | L89: =COUNTIF($K$2:K89,$K89)
A90: 89 | B90: =COUNTIF($C$2:$C90,模板!$E$2) | C90: =IFERROR(VLOOKUP(K90,开票信息!$A:$C,3,0),"") | D90: Lycocelle绽家四季繁花香氛洗衣液600ml（白兰花与栀子花）-方瓶 | F90: 13 | G90: =IFERROR(H90/F90,"") | H90: 234 | J90: 秋容 | K90: BMCLUB | L90: =COUNTIF($K$2:K90,$K90)
A91: 90 | B91: =COUNTIF($C$2:$C91,模板!$E$2) | C91: =IFERROR(VLOOKUP(K91,开票信息!$A:$C,3,0),"") | D91: Lycocelle绽家护衣留香珠（一杯鲜橙）180g | F91: 1 | G91: =IFERROR(H91/F91,"") | H91: 20 | J91: 秋容 | K91: BMCLUB | L91: =COUNTIF($K$2:K91,$K91)
... A156: 155 | B156: =COUNTIF($C$2:$C156,模板!$E$2) | C156: =IFERROR(VLOOKUP(K156,开票信息!$A:$C,3,0),"") | D156: 绽家香氛衣物小美盒-杏色款 | F156: 1 | G156: =IFERROR(H156/F156,"") | H156: 0 | J156: 秋容 | K156: BMCLUB | L156: =COUNTIF($K$2:K156,$K156)
A157: 156 | B157: =COUNTIF($C$2:$C157,模板!$E$2) | C157: BMCLUB（后台提现） | D157: Lycocelle绽家蓝桉叶三合一洗衣凝珠（忍冬与铃兰）12g*10颗 | F157: 7 | G157: =IFERROR(H157/F157,"") | H157: 56 | J157: 秋容 | K157: BMCLUB（后台提现） | L157: =COUNTIF($K$2:K157,$K157)
A158: 157 | B158: =COUNTIF($C$2:$C158,模板!$E$2) | C158: BMCLUB（后台提现） | D158: Lycocelle绽家香樟木条5根装（含收纳袋） | F158: 3 | G158: =IFERROR(H158/F158,"") | H158: 24 | J158: 秋容 | K158: BMCLUB（后台提现） | L158: =COUNTIF($K$2:K158,$K158)
A159: 158 | B159: =COUNTIF($C$2:$C159,模板!$E$2) | C159: BMCLUB（后台提现） | D159: Lycocelle绽家马赛皂洗碗液750ml-长嘴泵头（金） | F159: 41 | G159: =IFERROR(H159/F159,"") | H159: 0 | J159: 秋容 | K159: BMCLUB（后台提现） | L159: =COUNTIF($K$2:K159,$K159)
A160: 159 | B160: =COUNTIF($C$2:$C160,模板!$E$2) | C160: BMCLUB（后台提现） | D160: 绽家×亲密的奥黛丽·赫本香水油香氛洗衣凝珠40颗桶装（金钱桔/金橙与檀木鸢尾） | F160: 2 | G160: =IFERROR(H160/F160,"") | H160: 120 | J160: 秋容 | K160: BMCLUB（后台提现） | L160: =COUNTIF($K$2:K160,$K160)
A161: 160 | B161: =COUNTIF($C$2:$C161,模板!$E$2) | C161: BMCLUB（后台提现） | D161: 绽家×亲密的奥黛丽·赫本香水油香氛洗衣凝珠40颗桶装（金钱桔与檀木鸢尾） | F161: 1 | G161: =IFERROR(H161/F161,"") | H161: 60 | J161: 秋容 | K161: BMCLUB（后台提现） | L161: =COUNTIF($K$2:K161,$K161)
A162: 161 | B162: =COUNTIF($C$2:$C162,模板!$E$2) | C162: BMCLUB（后台提现） | D162: 绽家×亲密的奥黛丽·赫本香水油香氛洗衣凝珠40颗桶装（青柚与檀木鸢尾） | F162: 1 | G162: =IFERROR(H162/F162,"") | H162: 60 | J162: 秋容 | K162: BMCLUB（后台提现） | L162: =COUNTIF($K$2:K162,$K162)
A163: 162 | B163: =COUNTIF($C$2:$C163,模板!$E$2) | C163: BMCLUB（后台提现） | D163: 绽家×亲密的奥黛丽·赫本香水油香氛洗衣凝珠6颗袋装（青柚与檀木鸢尾） | F163: 5 | G163: =IFERROR(H163/F163,"") | H163: 0 | J163: 秋容 | K163: BMCLUB（后台提现） | L163: =COUNTIF($K$2:K163,$K163)
A164: 163 | B164: =COUNTIF($C$2:$C164,模板!$E$2) | C164: BMCLUB（后台提现） | D164: 绽家四季繁花酵素香氛洗衣液90ml（甜橙与翡翠百里香） | F164: 1 | G164: =IFERROR(H164/F164,"") | H164: 7 | J164: 秋容 | K164: BMCLUB（后台提现） | L164: =COUNTIF($K$2:K164,$K164)
A165: 164 | B165: =COUNTIF($C$2:$C165,模板!$E$2) | C165: BMCLUB（后台提现） | D165: 绽家四季繁花酵素香氛洗衣液90ml（迈索尔檀木与小花茉莉） | F165: 4 | G165: =IFERROR(H165/F165,"") | H165: 28 | J165: 秋容 | K165: BMCLUB（后台提现） | L165: =COUNTIF($K$2:K165,$K165)
A166: 165 | B166: =COUNTIF($C$2:$C166,模板!$E$2) | C166: BMCLUB（后台提现） | D166: 绽家四季繁花香氛衣物柔顺剂120ml（白兰花与栀子花）-袋装 120ml | F166: 2 | G166: =IFERROR(H166/F166,"") | H166: 12 | J166: 秋容 | K166: BMCLUB（后台提现） | L166: =COUNTIF($K$2:K166,$K166)
A167: 166 | B167: =COUNTIF($C$2:$C167,模板!$E$2) | C167: BMCLUB（后台提现） | D167: 绽家多用途海绵清洁擦（单个） | F167: 9 | G167: =IFERROR(H167/F167,"") | H167: 18 | J167: 秋容 | K167: BMCLUB（后台提现） | L167: =COUNTIF($K$2:K167,$K167)
A168: 167 | B168: =COUNTIF($C$2:$C168,模板!$E$2) | C168: BMCLUB（后台提现） | D168: 绽家多用途香氛球（三秋桂子）-6颗装 | F168: 2 | G168: =IFERROR(H168/F168,"") | H168: 29 | J168: 秋容 | K168: BMCLUB（后台提现） | L168: =COUNTIF($K$2:K168,$K168)
...
